#Expyriment 0.11.dev5 (Python 3.11.9), .xpe-file, coding: cp1252
#date: Wed Jan 08 2025 09:49:25
#sha1: 240fe4
#modules: 
#display: size=(800, 600), window_mode=False, opengl=2
#os: uname_result(system='Windows', node='Geoff3', release='10', version='10.0.22631', machine='AMD64')
Time,Type,Event,Value,Detail,Detail2
5255,stderr,received,'Traceback (most recent call last):'
5255,stderr,received,'  File "C:\\Users\\ali_a\\Desktop\\Single_Word_Processing_Stage\\.venv\\Lib\\site-packages\\pandas\\core\\indexes\\base.py", line 3805, in get_loc'
5305,stderr,received,'    return self._engine.get_loc(casted_key)'
5305,stderr,received,'           ^^^^^^^^^^^^^^^^^^^^^^^^^^^^^^^^'
5305,stderr,received,'  File "index.pyx", line 167, in pandas._libs.index.IndexEngine.get_loc'
5306,stderr,received,'  File "index.pyx", line 196, in pandas._libs.index.IndexEngine.get_loc'
5307,stderr,received,'  File "pandas\\\\_libs\\\\hashtable_class_helper.pxi", line 7081, in pandas._libs.hashtable.PyObjectHashTable.get_item'
5309,stderr,received,'  File "pandas\\\\_libs\\\\hashtable_class_helper.pxi", line 7089, in pandas._libs.hashtable.PyObjectHashTable.get_item'
5310,stderr,received,"KeyError: 'category'"
5310,stderr,received,''
5310,stderr,received,'The above exception was the direct cause of the following exception:'
5310,stderr,received,''
5310,stderr,received,'Traceback (most recent call last):'
5311,stderr,received,'  File "C:\\Users\\ali_a\\Desktop\\Single_Word_Processing_Stage\\Single_Word_Processing\\Christophe_Stimulation\\lexdec_v4.py", line 38, in <module>'
5311,stderr,received,"    trials = [(row['category'], row['item'], stimuli.TextLine(row['item']))"
5311,stderr,received,'             ^^^^^^^^^^^^^^^^^^^^^^^^^^^^^^^^^^^^^^^^^^^^^^^^^^^^^^^^^^^^^^'
5311,stderr,received,'  File "C:\\Users\\ali_a\\Desktop\\Single_Word_Processing_Stage\\Single_Word_Processing\\Christophe_Stimulation\\lexdec_v4.py", line 38, in <listcomp>'
5312,stderr,received,"    trials = [(row['category'], row['item'], stimuli.TextLine(row['item']))"
5312,stderr,received,'               ~~~^^^^^^^^^^^^'
5312,stderr,received,'  File "C:\\Users\\ali_a\\Desktop\\Single_Word_Processing_Stage\\.venv\\Lib\\site-packages\\pandas\\core\\series.py", line 1121, in __getitem__'
5362,stderr,received,'    return self._get_value(key)'
5363,stderr,received,'           ^^^^^^^^^^^^^^^^^^^^'
5363,stderr,received,'  File "C:\\Users\\ali_a\\Desktop\\Single_Word_Processing_Stage\\.venv\\Lib\\site-packages\\pandas\\core\\series.py", line 1237, in _get_value'
5364,stderr,received,'    loc = self.index.get_loc(label)'
5364,stderr,received,'          ^^^^^^^^^^^^^^^^^^^^^^^^^'
5365,stderr,received,'  File "C:\\Users\\ali_a\\Desktop\\Single_Word_Processing_Stage\\.venv\\Lib\\site-packages\\pandas\\core\\indexes\\base.py", line 3812, in get_loc'
5367,stderr,received,'    raise KeyError(key) from err'
5367,stderr,received,"KeyError: 'category'"
