#Expyriment 0.11.dev5 (Python 3.11.9), .xpe-file, coding: cp1252
#date: Wed Jan 08 2025 15:17:20
#sha1: fed5d2
#modules: 
#display: size=(800, 600), window_mode=False, opengl=2
#os: uname_result(system='Windows', node='Geoff3', release='10', version='10.0.22631', machine='AMD64')
Time,Type,Event,Value,Detail,Detail2
5241,stderr,received,'Traceback (most recent call last):'
5242,stderr,received,'  File "C:\\Users\\ali_a\\Desktop\\Single_Word_Processing_Stage\\.venv\\Lib\\site-packages\\pandas\\core\\indexes\\base.py", line 3805, in get_loc'
5244,stderr,received,'    return self._engine.get_loc(casted_key)'
5244,stderr,received,'           ^^^^^^^^^^^^^^^^^^^^^^^^^^^^^^^^'
5244,stderr,received,'  File "index.pyx", line 167, in pandas._libs.index.IndexEngine.get_loc'
5245,stderr,received,'  File "index.pyx", line 196, in pandas._libs.index.IndexEngine.get_loc'
5245,stderr,received,'  File "pandas\\\\_libs\\\\hashtable_class_helper.pxi", line 7081, in pandas._libs.hashtable.PyObjectHashTable.get_item'
5246,stderr,received,'  File "pandas\\\\_libs\\\\hashtable_class_helper.pxi", line 7089, in pandas._libs.hashtable.PyObjectHashTable.get_item'
5247,stderr,received,"KeyError: 'Audio_Male'"
5247,stderr,received,''
5247,stderr,received,'The above exception was the direct cause of the following exception:'
5247,stderr,received,''
5247,stderr,received,'Traceback (most recent call last):'
5247,stderr,received,'  File "C:\\Users\\ali_a\\Desktop\\Single_Word_Processing_Stage\\Single_Word_Processing\\Christophe_Stimulation\\lexdec_v4.py", line 30, in <module>'
5248,stderr,received,"    trials = [(row['Word'], row['Condition'], row['Audio_Male'], row['Audio_Female'])"
5248,stderr,received,'             ^^^^^^^^^^^^^^^^^^^^^^^^^^^^^^^^^^^^^^^^^^^^^^^^^^^^^^^^^^^^^^^^^^^^^^^^'
5248,stderr,received,'  File "C:\\Users\\ali_a\\Desktop\\Single_Word_Processing_Stage\\Single_Word_Processing\\Christophe_Stimulation\\lexdec_v4.py", line 30, in <listcomp>'
5249,stderr,received,"    trials = [(row['Word'], row['Condition'], row['Audio_Male'], row['Audio_Female'])"
5249,stderr,received,'                                              ~~~^^^^^^^^^^^^^^'
5249,stderr,received,'  File "C:\\Users\\ali_a\\Desktop\\Single_Word_Processing_Stage\\.venv\\Lib\\site-packages\\pandas\\core\\series.py", line 1121, in __getitem__'
5250,stderr,received,'    return self._get_value(key)'
5250,stderr,received,'           ^^^^^^^^^^^^^^^^^^^^'
5250,stderr,received,'  File "C:\\Users\\ali_a\\Desktop\\Single_Word_Processing_Stage\\.venv\\Lib\\site-packages\\pandas\\core\\series.py", line 1237, in _get_value'
5250,stderr,received,'    loc = self.index.get_loc(label)'
5251,stderr,received,'          ^^^^^^^^^^^^^^^^^^^^^^^^^'
5251,stderr,received,'  File "C:\\Users\\ali_a\\Desktop\\Single_Word_Processing_Stage\\.venv\\Lib\\site-packages\\pandas\\core\\indexes\\base.py", line 3812, in get_loc'
5252,stderr,received,'    raise KeyError(key) from err'
5252,stderr,received,"KeyError: 'Audio_Male'"
